Workbook

Sheet 10 Trial Balance 
A1: Account_No | B1: Account_Name | C1: Unadjusted_Debit | D1: Unadjusted_Credit | E1: Adjustments_Debit | F1: Adjustments_Credit | G1: Adjusted_Debit | H1: Adjusted_Credit | I1: HST_Eligible | J1: ITC_Amount
A2: ASSETS | G2: =IF(ABS(IF(Table3[[#This Row],[Unadjusted_Debit]]>=0,Table3[[#This Row],[Unadjusted_Debit]]+Table3[[#This Row],[Adjustments_Debit]]-Table3[[#This Row],[Adjustments_Credit]],"0"))=0,"",(ABS(IF(Table3[[#This Row],[Unadjusted_Debit]]>=0,Table3[[#This Row],[Unadjusted_Debit]]+Table3[[#This Row],[Adjustments_Debit]]-Table3[[#This Row],[Adjustments_Credit]],"0")))) | H2: =IF(Table3[[#This Row],[Unadjusted_Credit]]>0,Table3[[#This Row],[Unadjusted_Credit]]+Table3[[#This Row],[Adjustments_Credit]]-Table3[[#This Row],[Adjustments_Debit]],"") | J2: =IF(Table3[[#This Row],[HST_Eligible]]="YES",Table3[[#This Row],[Adjusted_Debit]]*0.13,IF(Table3[[#This Row],[Adjusted_Debit]]="Partial",Table3[[#Headers],[Adjusted_Debit]]*0.13*0.5,IF(Table3[[#This Row],[HST_Eligible]]="NO",0,"")))
A3: 1000 | B3: Cash | C3: 82875.5 | F3: 375 | G3: =IF(ABS(IF(Table3[[#This Row],[Unadjusted_Debit]]>=0,Table3[[#This Row],[Unadjusted_Debit]]+Table3[[#This Row],[Adjustments_Debit]]-Table3[[#This Row],[Adjustments_Credit]],"0"))=0,"",(ABS(IF(Table3[[#This Row],[Unadjusted_Debit]]>=0,Table3[[#This Row],[Unadjusted_Debit]]+Table3[[#This Row],[Adjustments_Debit]]-Table3[[#This Row],[Adjustments_Credit]],"0")))) -> 82500.5 | H3: =IF(Table3[[#This Row],[Unadjusted_Credit]]>0,Table3[[#This Row],[Unadjusted_Credit]]+Table3[[#This Row],[Adjustments_Credit]]-Table3[[#This Row],[Adjustments_Debit]],"") | I3: N/A | J3: =IF(Table3[[#This Row],[HST_Eligible]]="YES",Table3[[#This Row],[Adjusted_Debit]]*0.13,IF(Table3[[#This Row],[Adjusted_Debit]]="Partial",Table3[[#Headers],[Adjusted_Debit]]*0.13*0.5,IF(Table3[[#This Row],[HST_Eligible]]="NO",0,"")))
A4: 1010 | B4: Petty Cash | C4: 500 | G4: =IF(ABS(IF(Table3[[#This Row],[Unadjusted_Debit]]>=0,Table3[[#This Row],[Unadjusted_Debit]]+Table3[[#This Row],[Adjustments_Debit]]-Table3[[#This Row],[Adjustments_Credit]],"0"))=0,"",(ABS(IF(Table3[[#This Row],[Unadjusted_Debit]]>=0,Table3[[#This Row],[Unadjusted_Debit]]+Table3[[#This Row],[Adjustments_Debit]]-Table3[[#This Row],[Adjustments_Credit]],"0")))) -> 500 | H4: =IF(Table3[[#This Row],[Unadjusted_Credit]]>0,Table3[[#This Row],[Unadjusted_Credit]]+Table3[[#This Row],[Adjustments_Credit]]-Table3[[#This Row],[Adjustments_Debit]],"") | I4: N/A | J4: =IF(Table3[[#This Row],[HST_Eligible]]="YES",Table3[[#This Row],[Adjusted_Debit]]*0.13,IF(Table3[[#This Row],[Adjusted_Debit]]="Partial",Table3[[#Headers],[Adjusted_Debit]]*0.13*0.5,IF(Table3[[#This Row],[HST_Eligible]]="NO",0,"")))
A5: 1100 | B5: Accounts Receivable | C5: 715200 | E5: 350 | G5: =IF(ABS(IF(Table3[[#This Row],[Unadjusted_Debit]]>=0,Table3[[#This Row],[Unadjusted_Debit]]+Table3[[#This Row],[Adjustments_Debit]]-Table3[[#This Row],[Adjustments_Credit]],"0"))=0,"",(ABS(IF(Table3[[#This Row],[Unadjusted_Debit]]>=0,Table3[[#This Row],[Unadjusted_Debit]]+Table3[[#This Row],[Adjustments_Debit]]-Table3[[#This Row],[Adjustments_Credit]],"0")))) -> 715550 | H5: =IF(Table3[[#This Row],[Unadjusted_Credit]]>0,Table3[[#This Row],[Unadjusted_Credit]]+Table3[[#This Row],[Adjustments_Credit]]-Table3[[#This Row],[Adjustments_Debit]],"") | I5: N/A | J5: =IF(Table3[[#This Row],[HST_Eligible]]="YES",Table3[[#This Row],[Adjusted_Debit]]*0.13,IF(Table3[[#This Row],[Adjusted_Debit]]="Partial",Table3[[#Headers],[Adjusted_Debit]]*0.13*0.5,IF(Table3[[#This Row],[HST_Eligible]]="NO",0,"")))
A6: 1110 | B6: Allowance for Doubtful Accounts | D6: 12000 | F6: 652 | G6: =IF(ABS(IF(Table3[[#This Row],[Unadjusted_Debit]]>=0,Table3[[#This Row],[Unadjusted_Debit]]+Table3[[#This Row],[Adjustments_Debit]]-Table3[[#This Row],[Adjustments_Credit]],"0"))=0,"",(ABS(IF(Table3[[#This Row],[Unadjusted_Debit]]>=0,Table3[[#This Row],[Unadjusted_Debit]]+Table3[[#This Row],[Adjustments_Debit]]-Table3[[#This Row],[Adjustments_Credit]],"0")))) -> 652 | H6: =IF(Table3[[#This Row],[Unadjusted_Credit]]>0,Table3[[#This Row],[Unadjusted_Credit]]+Table3[[#This Row],[Adjustments_Credit]]-Table3[[#This Row],[Adjustments_Debit]],"") -> 12652 | I6: N/A | J6: =IF(Table3[[#This Row],[HST_Eligible]]="YES",Table3[[#This Row],[Adjusted_Debit]]*0.13,IF(Table3[[#This Row],[Adjusted_Debit]]="Partial",Table3[[#Headers],[Adjusted_Debit]]*0.13*0.5,IF(Table3[[#This Row],[HST_Eligible]]="NO",0,"")))
A7: 1200 | B7: Inventory - New Vehicles | C7: 450000 | F7: 800 | G7: =IF(ABS(IF(Table3[[#This Row],[Unadjusted_Debit]]>=0,Table3[[#This Row],[Unadjusted_Debit]]+Table3[[#This Row],[Adjustments_Debit]]-Table3[[#This Row],[Adjustments_Credit]],"0"))=0,"",(ABS(IF(Table3[[#This Row],[Unadjusted_Debit]]>=0,Table3[[#This Row],[Unadjusted_Debit]]+Table3[[#This Row],[Adjustments_Debit]]-Table3[[#This Row],[Adjustments_Credit]],"0")))) -> 449200 | H7: =IF(Table3[[#This Row],[Unadjusted_Credit]]>0,Table3[[#This Row],[Unadjusted_Credit]]+Table3[[#This Row],[Adjustments_Credit]]-Table3[[#This Row],[Adjustments_Debit]],"") | I7: N/A | J7: =IF(Table3[[#This Row],[HST_Eligible]]="YES",Table3[[#This Row],[Adjusted_Debit]]*0.13,IF(Table3[[#This Row],[Adjusted_Debit]]="Partial",Table3[[#Headers],[Adjusted_Debit]]*0.13*0.5,IF(Table3[[#This Row],[HST_Eligible]]="NO",0,"")))
A8: 1210 | B8: Inventory - Used Vehicles | C8: 125000 | G8: =IF(ABS(IF(Table3[[#This Row],[Unadjusted_Debit]]>=0,Table3[[#This Row],[Unadjusted_Debit]]+Table3[[#This Row],[Adjustments_Debit]]-Table3[[#This Row],[Adjustments_Credit]],"0"))=0,"",(ABS(IF(Table3[[#This Row],[Unadjusted_Debit]]>=0,Table3[[#This Row],[Unadjusted_Debit]]+Table3[[#This Row],[Adjustments_Debit]]-Table3[[#This Row],[Adjustments_Credit]],"0")))) -> 125000 | H8: =IF(Table3[[#This Row],[Unadjusted_Credit]]>0,Table3[[#This Row],[Unadjusted_Credit]]+Table3[[#This Row],[Adjustments_Credit]]-Table3[[#This Row],[Adjustments_Debit]],"") | I8: N/A | J8: =IF(Table3[[#This Row],[HST_Eligible]]="YES",Table3[[#This Row],[Adjusted_Debit]]*0.13,IF(Table3[[#This Row],[Adjusted_Debit]]="Partial",Table3[[#Headers],[Adjusted_Debit]]*0.13*0.5,IF(Table3[[#This Row],[HST_Eligible]]="NO",0,"")))
A9: 1220 | B9: Inventory - Parts | C9: 45600 | G9: =IF(ABS(IF(Table3[[#This Row],[Unadjusted_Debit]]>=0,Table3[[#This Row],[Unadjusted_Debit]]+Table3[[#This Row],[Adjustments_Debit]]-Table3[[#This Row],[Adjustments_Credit]],"0"))=0,"",(ABS(IF(Table3[[#This Row],[Unadjusted_Debit]]>=0,Table3[[#This Row],[Unadjusted_Debit]]+Table3[[#This Row],[Adjustments_Debit]]-Table3[[#This Row],[Adjustments_Credit]],"0")))) -> 45600 | H9: =IF(Table3[[#This Row],[Unadjusted_Credit]]>0,Table3[[#This Row],[Unadjusted_Credit]]+Table3[[#This Row],[Adjustments_Credit]]-Table3[[#This Row],[Adjustments_Debit]],"") | I9: N/A | J9: =IF(Table3[[#This Row],[HST_Eligible]]="YES",Table3[[#This Row],[Adjusted_Debit]]*0.13,IF(Table3[[#This Row],[Adjusted_Debit]]="Partial",Table3[[#Headers],[Adjusted_Debit]]*0.13*0.5,IF(Table3[[#This Row],[HST_Eligible]]="NO",0,"")))
A10: 1300 | B10: Prepaid Insurance | C10: 7200 | F10: 600 | G10: =IF(ABS(IF(Table3[[#This Row],[Unadjusted_Debit]]>=0,Table3[[#This Row],[Unadjusted_Debit]]+Table3[[#This Row],[Adjustments_Debit]]-Table3[[#This Row],[Adjustments_Credit]],"0"))=0,"",(ABS(IF(Table3[[#This Row],[Unadjusted_Debit]]>=0,Table3[[#This Row],[Unadjusted_Debit]]+Table3[[#This Row],[Adjustments_Debit]]-Table3[[#This Row],[Adjustments_Credit]],"0")))) -> 6600 | H10: =IF(Table3[[#This Row],[Unadjusted_Credit]]>0,Table3[[#This Row],[Unadjusted_Credit]]+Table3[[#This Row],[Adjustments_Credit]]-Table3[[#This Row],[Adjustments_Debit]],"") | I10: N/A | J10: =IF(Table3[[#This Row],[HST_Eligible]]="YES",Table3[[#This Row],[Adjusted_Debit]]*0.13,IF(Table3[[#This Row],[Adjusted_Debit]]="Partial",Table3[[#Headers],[Adjusted_Debit]]*0.13*0.5,IF(Table3[[#This Row],[HST_Eligible]]="NO",0,"")))
A11: 1400 | B11: Property, Plant & Equipment | C11: 250000 | G11: =IF(ABS(IF(Table3[[#This Row],[Unadjusted_Debit]]>=0,Table3[[#This Row],[Unadjusted_Debit]]+Table3[[#This Row],[Adjustments_Debit]]-Table3[[#This Row],[Adjustments_Credit]],"0"))=0,"",(ABS(IF(Table3[[#This Row],[Unadjusted_Debit]]>=0,Table3[[#This Row],[Unadjusted_Debit]]+Table3[[#This Row],[Adjustments_Debit]]-Table3[[#This Row],[Adjustments_Credit]],"0")))) -> 250000 | H11: =IF(Table3[[#This Row],[Unadjusted_Credit]]>0,Table3[[#This Row],[Unadjusted_Credit]]+Table3[[#This Row],[Adjustments_Credit]]-Table3[[#This Row],[Adjustments_Debit]],"") | I11: N/A | J11: =IF(Table3[[#This Row],[HST_Eligible]]="YES",Table3[[#This Row],[Adjusted_Debit]]*0.13,IF(Table3[[#This Row],[Adjusted_Debit]]="Partial",Table3[[#Headers],[Adjusted_Debit]]*0.13*0.5,IF(Table3[[#This Row],[HST_Eligible]]="NO",0,"")))
A12: 1410 | B12: Accumulated Depreciation | D12: 95000 | F12: 3750 | G12: =IF(ABS(IF(Table3[[#This Row],[Unadjusted_Debit]]>=0,Table3[[#This Row],[Unadjusted_Debit]]+Table3[[#This Row],[Adjustments_Debit]]-Table3[[#This Row],[Adjustments_Credit]],"0"))=0,"",(ABS(IF(Table3[[#This Row],[Unadjusted_Debit]]>=0,Table3[[#This Row],[Unadjusted_Debit]]+Table3[[#This Row],[Adjustments_Debit]]-Table3[[#This Row],[Adjustments_Credit]],"0")))) -> 3750 | H12: =IF(Table3[[#This Row],[Unadjusted_Credit]]>0,Table3[[#This Row],[Unadjusted_Credit]]+Table3[[#This Row],[Adjustments_Credit]]-Table3[[#This Row],[Adjustments_Debit]],"") -> 98750 | I12: N/A | J12: =IF(Table3[[#This Row],[HST_Eligible]]="YES",Table3[[#This Row],[Adjusted_Debit]]*0.13,IF(Table3[[#This Row],[Adjusted_Debit]]="Partial",Table3[[#Headers],[Adjusted_Debit]]*0.13*0.5,IF(Table3[[#This Row],[HST_Eligible]]="NO",0,"")))
G13: =IF(ABS(IF(Table3[[#This Row],[Unadjusted_Debit]]>=0,Table3[[#This Row],[Unadjusted_Debit]]+Table3[[#This Row],[Adjustments_Debit]]-Table3[[#This Row],[Adjustments_Credit]],"0"))=0,"",(ABS(IF(Table3[[#This Row],[Unadjusted_Debit]]>=0,Table3[[#This Row],[Unadjusted_Debit]]+Table3[[#This Row],[Adjustments_Debit]]-Table3[[#This Row],[Adjustments_Credit]],"0")))) | H13: =IF(Table3[[#This Row],[Unadjusted_Credit]]>0,Table3[[#This Row],[Unadjusted_Credit]]+Table3[[#This Row],[Adjustments_Credit]]-Table3[[#This Row],[Adjustments_Debit]],"") | J13: =IF(Table3[[#This Row],[HST_Eligible]]="YES",Table3[[#This Row],[Adjusted_Debit]]*0.13,IF(Table3[[#This Row],[Adjusted_Debit]]="Partial",Table3[[#Headers],[Adjusted_Debit]]*0.13*0.5,IF(Table3[[#This Row],[HST_Eligible]]="NO",0,"")))
A14: LIABILITIES | G14: =IF(ABS(IF(Table3[[#This Row],[Unadjusted_Debit]]>=0,Table3[[#This Row],[Unadjusted_Debit]]+Table3[[#This Row],[Adjustments_Debit]]-Table3[[#This Row],[Adjustments_Credit]],"0"))=0,"",(ABS(IF(Table3[[#This Row],[Unadjusted_Debit]]>=0,Table3[[#This Row],[Unadjusted_Debit]]+Table3[[#This Row],[Adjustments_Debit]]-Table3[[#This Row],[Adjustments_Credit]],"0")))) | H14: =IF(Table3[[#This Row],[Unadjusted_Credit]]>0,Table3[[#This Row],[Unadjusted_Credit]]+Table3[[#This Row],[Adjustments_Credit]]-Table3[[#This Row],[Adjustments_Debit]],"") | J14: =IF(Table3[[#This Row],[HST_Eligible]]="YES",Table3[[#This Row],[Adjusted_Debit]]*0.13,IF(Table3[[#This Row],[Adjusted_Debit]]="Partial",Table3[[#Headers],[Adjusted_Debit]]*0.13*0.5,IF(Table3[[#This Row],[HST_Eligible]]="NO",0,"")))
A15: 2000 | B15: Accounts Payable | D15: 125300 | G15: =IF(ABS(IF(Table3[[#This Row],[Unadjusted_Debit]]>=0,Table3[[#This Row],[Unadjusted_Debit]]+Table3[[#This Row],[Adjustments_Debit]]-Table3[[#This Row],[Adjustments_Credit]],"0"))=0,"",(ABS(IF(Table3[[#This Row],[Unadjusted_Debit]]>=0,Table3[[#This Row],[Unadjusted_Debit]]+Table3[[#This Row],[Adjustments_Debit]]-Table3[[#This Row],[Adjustments_Credit]],"0")))) | H15: =IF(Table3[[#This Row],[Unadjusted_Credit]]>0,Table3[[#This Row],[Unadjusted_Credit]]+Table3[[#This Row],[Adjustments_Credit]]-Table3[[#This Row],[Adjustments_Debit]],"") -> 125300 | I15: N/A | J15: =IF(Table3[[#This Row],[HST_Eligible]]="YES",Table3[[#This Row],[Adjusted_Debit]]*0.13,IF(Table3[[#This Row],[Adjusted_Debit]]="Partial",Table3[[#Headers],[Adjusted_Debit]]*0.13*0.5,IF(Table3[[#This Row],[HST_Eligible]]="NO",0,"")))
A16: 2010 | B16: Credit Card Payable | D16: 5372 | G16: =IF(ABS(IF(Table3[[#This Row],[Unadjusted_Debit]]>=0,Table3[[#This Row],[Unadjusted_Debit]]+Table3[[#This Row],[Adjustments_Debit]]-Table3[[#This Row],[Adjustments_Credit]],"0"))=0,"",(ABS(IF(Table3[[#This Row],[Unadjusted_Debit]]>=0,Table3[[#This Row],[Unadjusted_Debit]]+Table3[[#This Row],[Adjustments_Debit]]-Table3[[#This Row],[Adjustments_Credit]],"0")))) | H16: =IF(Table3[[#This Row],[Unadjusted_Credit]]>0,Table3[[#This Row],[Unadjusted_Credit]]+Table3[[#This Row],[Adjustments_Credit]]-Table3[[#This Row],[Adjustments_Debit]],"") -> 5372 | I16: N/A | J16: =IF(Table3[[#This Row],[HST_Eligible]]="YES",Table3[[#This Row],[Adjusted_Debit]]*0.13,IF(Table3[[#This Row],[Adjusted_Debit]]="Partial",Table3[[#Headers],[Adjusted_Debit]]*0.13*0.5,IF(Table3[[#This Row],[HST_Eligible]]="NO",0,"")))
A17: 2100 | B17: HST Payable | D17: 16900 | G17: =IF(ABS(IF(Table3[[#This Row],[Unadjusted_Debit]]>=0,Table3[[#This Row],[Unadjusted_Debit]]+Table3[[#This Row],[Adjustments_Debit]]-Table3[[#This Row],[Adjustments_Credit]],"0"))=0,"",(ABS(IF(Table3[[#This Row],[Unadjusted_Debit]]>=0,Table3[[#This Row],[Unadjusted_Debit]]+Table3[[#This Row],[Adjustments_Debit]]-Table3[[#This Row],[Adjustments_Credit]],"0")))) | H17: =IF(Table3[[#This Row],[Unadjusted_Credit]]>0,Table3[[#This Row],[Unadjusted_Credit]]+Table3[[#This Row],[Adjustments_Credit]]-Table3[[#This Row],[Adjustments_Debit]],"") -> 16900 | I17: N/A | J17: =IF(Table3[[#This Row],[HST_Eligible]]="YES",Table3[[#This Row],[Adjusted_Debit]]*0.13,IF(Table3[[#This Row],[Adjusted_Debit]]="Partial",Table3[[#Headers],[Adjusted_Debit]]*0.13*0.5,IF(Table3[[#This Row],[HST_Eligible]]="NO",0,"")))
A18: 2200 | B18: Payroll Liabilities | D18: 18450 | E18: 3400 | G18: =IF(ABS(IF(Table3[[#This Row],[Unadjusted_Debit]]>=0,Table3[[#This Row],[Unadjusted_Debit]]+Table3[[#This Row],[Adjustments_Debit]]-Table3[[#This Row],[Adjustments_Credit]],"0"))=0,"",(ABS(IF(Table3[[#This Row],[Unadjusted_Debit]]>=0,Table3[[#This Row],[Unadjusted_Debit]]+Table3[[#This Row],[Adjustments_Debit]]-Table3[[#This Row],[Adjustments_Credit]],"0")))) -> 3400 | H18: =Table3[[#This Row],[Adjusted_Debit]]+Table3[[#This Row],[Unadjusted_Credit]] -> 21850 | I18: N/A | J18: =IF(Table3[[#This Row],[HST_Eligible]]="YES",Table3[[#This Row],[Adjusted_Debit]]*0.13,IF(Table3[[#This Row],[Adjusted_Debit]]="Partial",Table3[[#Headers],[Adjusted_Debit]]*0.13*0.5,IF(Table3[[#This Row],[HST_Eligible]]="NO",0,"")))
A19: 2300 | B19: Interest Payable | D19: 0 | F19: 400 | G19: =IF(ABS(IF(Table3[[#This Row],[Unadjusted_Debit]]>=0,Table3[[#This Row],[Unadjusted_Debit]]+Table3[[#This Row],[Adjustments_Debit]]-Table3[[#This Row],[Adjustments_Credit]],"0"))=0,"",(ABS(IF(Table3[[#This Row],[Unadjusted_Debit]]>=0,Table3[[#This Row],[Unadjusted_Debit]]+Table3[[#This Row],[Adjustments_Debit]]-Table3[[#This Row],[Adjustments_Credit]],"0")))) -> 400 | H19: 400 | I19: N/A | J19: =IF(Table3[[#This Row],[HST_Eligible]]="YES",Table3[[#This Row],[Adjusted_Debit]]*0.13,IF(Table3[[#This Row],[Adjusted_Debit]]="Partial",Table3[[#Headers],[Adjusted_Debit]]*0.13*0.5,IF(Table3[[#This Row],[HST_Eligible]]="NO",0,"")))
A20: 2400 | B20: Long-term Debt | D20: 80000 | G20: =IF(ABS(IF(Table3[[#This Row],[Unadjusted_Debit]]>=0,Table3[[#This Row],[Unadjusted_Debit]]+Table3[[#This Row],[Adjustments_Debit]]-Table3[[#This Row],[Adjustments_Credit]],"0"))=0,"",(ABS(IF(Table3[[#This Row],[Unadjusted_Debit]]>=0,Table3[[#This Row],[Unadjusted_Debit]]+Table3[[#This Row],[Adjustments_Debit]]-Table3[[#This Row],[Adjustments_Credit]],"0")))) | H20: =IF(Table3[[#This Row],[Unadjusted_Credit]]>0,Table3[[#This Row],[Unadjusted_Credit]]+Table3[[#This Row],[Adjustments_Credit]]-Table3[[#This Row],[Adjustments_Debit]],"") -> 80000 | I20: N/A | J20: =IF(Table3[[#This Row],[HST_Eligible]]="YES",Table3[[#This Row],[Adjusted_Debit]]*0.13,IF(Table3[[#This Row],[Adjusted_Debit]]="Partial",Table3[[#Headers],[Adjusted_Debit]]*0.13*0.5,IF(Table3[[#This Row],[HST_Eligible]]="NO",0,"")))
G21: =IF(ABS(IF(Table3[[#This Row],[Unadjusted_Debit]]>=0,Table3[[#This Row],[Unadjusted_Debit]]+Table3[[#This Row],[Adjustments_Debit]]-Table3[[#This Row],[Adjustments_Credit]],"0"))=0,"",(ABS(IF(Table3[[#This Row],[Unadjusted_Debit]]>=0,Table3[[#This Row],[Unadjusted_Debit]]+Table3[[#This Row],[Adjustments_Debit]]-Table3[[#This Row],[Adjustments_Credit]],"0")))) | H21: =IF(Table3[[#This Row],[Unadjusted_Credit]]>0,Table3[[#This Row],[Unadjusted_Credit]]+Table3[[#This Row],[Adjustments_Credit]]-Table3[[#This Row],[Adjustments_Debit]],"") | J21: =IF(Table3[[#This Row],[HST_Eligible]]="YES",Table3[[#This Row],[Adjusted_Debit]]*0.13,IF(Table3[[#This Row],[Adjusted_Debit]]="Partial",Table3[[#Headers],[Adjusted_Debit]]*0.13*0.5,IF(Table3[[#This Row],[HST_Eligible]]="NO",0,"")))
A22: EQUITY | G22: =IF(ABS(IF(Table3[[#This Row],[Unadjusted_Debit]]>=0,Table3[[#This Row],[Unadjusted_Debit]]+Table3[[#This Row],[Adjustments_Debit]]-Table3[[#This Row],[Adjustments_Credit]],"0"))=0,"",(ABS(IF(Table3[[#This Row],[Unadjusted_Debit]]>=0,Table3[[#This Row],[Unadjusted_Debit]]+Table3[[#This Row],[Adjustments_Debit]]-Table3[[#This Row],[Adjustments_Credit]],"0")))) | H22: =IF(Table3[[#This Row],[Unadjusted_Credit]]>0,Table3[[#This Row],[Unadjusted_Credit]]+Table3[[#This Row],[Adjustments_Credit]]-Table3[[#This Row],[Adjustments_Debit]],"") | J22: =IF(Table3[[#This Row],[HST_Eligible]]="YES",Table3[[#This Row],[Adjusted_Debit]]*0.13,IF(Table3[[#This Row],[Adjusted_Debit]]="Partial",Table3[[#Headers],[Adjusted_Debit]]*0.13*0.5,IF(Table3[[#This Row],[HST_Eligible]]="NO",0,"")))
A23: 3000 | B23: Owner's Equity | D23: 450000 | G23: =IF(ABS(IF(Table3[[#This Row],[Unadjusted_Debit]]>=0,Table3[[#This Row],[Unadjusted_Debit]]+Table3[[#This Row],[Adjustments_Debit]]-Table3[[#This Row],[Adjustments_Credit]],"0"))=0,"",(ABS(IF(Table3[[#This Row],[Unadjusted_Debit]]>=0,Table3[[#This Row],[Unadjusted_Debit]]+Table3[[#This Row],[Adjustments_Debit]]-Table3[[#This Row],[Adjustments_Credit]],"0")))) | H23: =IF(Table3[[#This Row],[Unadjusted_Credit]]>0,Table3[[#This Row],[Unadjusted_Credit]]+Table3[[#This Row],[Adjustments_Credit]]-Table3[[#This Row],[Adjustments_Debit]],"") -> 450000 | I23: N/A | J23: =IF(Table3[[#This Row],[HST_Eligible]]="YES",Table3[[#This Row],[Adjusted_Debit]]*0.13,IF(Table3[[#This Row],[Adjusted_Debit]]="Partial",Table3[[#Headers],[Adjusted_Debit]]*0.13*0.5,IF(Table3[[#This Row],[HST_Eligible]]="NO",0,"")))
G24: =IF(ABS(IF(Table3[[#This Row],[Unadjusted_Debit]]>=0,Table3[[#This Row],[Unadjusted_Debit]]+Table3[[#This Row],[Adjustments_Debit]]-Table3[[#This Row],[Adjustments_Credit]],"0"))=0,"",(ABS(IF(Table3[[#This Row],[Unadjusted_Debit]]>=0,Table3[[#This Row],[Unadjusted_Debit]]+Table3[[#This Row],[Adjustments_Debit]]-Table3[[#This Row],[Adjustments_Credit]],"0")))) | H24: =IF(Table3[[#This Row],[Unadjusted_Credit]]>0,Table3[[#This Row],[Unadjusted_Credit]]+Table3[[#This Row],[Adjustments_Credit]]-Table3[[#This Row],[Adjustments_Debit]],"") | J24: =IF(Table3[[#This Row],[HST_Eligible]]="YES",Table3[[#This Row],[Adjusted_Debit]]*0.13,IF(Table3[[#This Row],[Adjusted_Debit]]="Partial",Table3[[#Headers],[Adjusted_Debit]]*0.13*0.5,IF(Table3[[#This Row],[HST_Eligible]]="NO",0,"")))
A25: REVENUE | G25: =IF(ABS(IF(Table3[[#This Row],[Unadjusted_Debit]]>=0,Table3[[#This Row],[Unadjusted_Debit]]+Table3[[#This Row],[Adjustments_Debit]]-Table3[[#This Row],[Adjustments_Credit]],"0"))=0,"",(ABS(IF(Table3[[#This Row],[Unadjusted_Debit]]>=0,Table3[[#This Row],[Unadjusted_Debit]]+Table3[[#This Row],[Adjustments_Debit]]-Table3[[#This Row],[Adjustments_Credit]],"0")))) | H25: =IF(Table3[[#This Row],[Unadjusted_Credit]]>0,Table3[[#This Row],[Unadjusted_Credit]]+Table3[[#This Row],[Adjustments_Credit]]-Table3[[#This Row],[Adjustments_Debit]],"") | J25: =IF(Table3[[#This Row],[HST_Eligible]]="YES",Table3[[#This Row],[Adjusted_Debit]]*0.13,IF(Table3[[#This Row],[Adjusted_Debit]]="Partial",Table3[[#Headers],[Adjusted_Debit]]*0.13*0.5,IF(Table3[[#This Row],[HST_Eligible]]="NO",0,"")))
A26: 4000 | B26: Sales Revenue - New Vehicles | D26: 1250000 | E26: 180 | G26: =IF(ABS(IF(Table3[[#This Row],[Unadjusted_Debit]]>=0,Table3[[#This Row],[Unadjusted_Debit]]+Table3[[#This Row],[Adjustments_Debit]]-Table3[[#This Row],[Adjustments_Credit]],"0"))=0,"",(ABS(IF(Table3[[#This Row],[Unadjusted_Debit]]>=0,Table3[[#This Row],[Unadjusted_Debit]]+Table3[[#This Row],[Adjustments_Debit]]-Table3[[#This Row],[Adjustments_Credit]],"0")))) -> 180 | H26: =IF(Table3[[#This Row],[Unadjusted_Credit]]>0,Table3[[#This Row],[Unadjusted_Credit]]+Table3[[#This Row],[Adjustments_Credit]]-Table3[[#This Row],[Adjustments_Debit]],"") -> 1249820 | I26: N/A | J26: =IF(Table3[[#This Row],[HST_Eligible]]="YES",Table3[[#This Row],[Adjusted_Debit]]*0.13,IF(Table3[[#This Row],[Adjusted_Debit]]="Partial",Table3[[#Headers],[Adjusted_Debit]]*0.13*0.5,IF(Table3[[#This Row],[HST_Eligible]]="NO",0,"")))
A27: 4010 | B27: Sales Revenue - Used Vehicles | D27: 485000 | G27: =IF(ABS(IF(Table3[[#This Row],[Unadjusted_Debit]]>=0,Table3[[#This Row],[Unadjusted_Debit]]+Table3[[#This Row],[Adjustments_Debit]]-Table3[[#This Row],[Adjustments_Credit]],"0"))=0,"",(ABS(IF(Table3[[#This Row],[Unadjusted_Debit]]>=0,Table3[[#This Row],[Unadjusted_Debit]]+Table3[[#This Row],[Adjustments_Debit]]-Table3[[#This Row],[Adjustments_Credit]],"0")))) | H27: =IF(Table3[[#This Row],[Unadjusted_Credit]]>0,Table3[[#This Row],[Unadjusted_Credit]]+Table3[[#This Row],[Adjustments_Credit]]-Table3[[#This Row],[Adjustments_Debit]],"") -> 485000 | I27: N/A | J27: =IF(Table3[[#This Row],[HST_Eligible]]="YES",Table3[[#This Row],[Adjusted_Debit]]*0.13,IF(Table3[[#This Row],[Adjusted_Debit]]="Partial",Table3[[#Headers],[Adjusted_Debit]]*0.13*0.5,IF(Table3[[#This Row],[HST_Eligible]]="NO",0,"")))
A28: 4020 | B28: Service Revenue | D28: 325000 | G28: =IF(ABS(IF(Table3[[#This Row],[Unadjusted_Debit]]>=0,Table3[[#This Row],[Unadjusted_Debit]]+Table3[[#This Row],[Adjustments_Debit]]-Table3[[#This Row],[Adjustments_Credit]],"0"))=0,"",(ABS(IF(Table3[[#This Row],[Unadjusted_Debit]]>=0,Table3[[#This Row],[Unadjusted_Debit]]+Table3[[#This Row],[Adjustments_Debit]]-Table3[[#This Row],[Adjustments_Credit]],"0")))) | H28: =IF(Table3[[#This Row],[Unadjusted_Credit]]>0,Table3[[#This Row],[Unadjusted_Credit]]+Table3[[#This Row],[Adjustments_Credit]]-Table3[[#This Row],[Adjustments_Debit]],"") -> 325000 | I28: N/A | J28: =IF(Table3[[#This Row],[HST_Eligible]]="YES",Table3[[#This Row],[Adjusted_Debit]]*0.13,IF(Table3[[#This Row],[Adjusted_Debit]]="Partial",Table3[[#Headers],[Adjusted_Debit]]*0.13*0.5,IF(Table3[[#This Row],[HST_Eligible]]="NO",0,"")))
A29: 4030 | B29: Parts Revenue | D29: 158000 | G29: =IF(ABS(IF(Table3[[#This Row],[Unadjusted_Debit]]>=0,Table3[[#This Row],[Unadjusted_Debit]]+Table3[[#This Row],[Adjustments_Debit]]-Table3[[#This Row],[Adjustments_Credit]],"0"))=0,"",(ABS(IF(Table3[[#This Row],[Unadjusted_Debit]]>=0,Table3[[#This Row],[Unadjusted_Debit]]+Table3[[#This Row],[Adjustments_Debit]]-Table3[[#This Row],[Adjustments_Credit]],"0")))) | H29: =IF(Table3[[#This Row],[Unadjusted_Credit]]>0,Table3[[#This Row],[Unadjusted_Credit]]+Table3[[#This Row],[Adjustments_Credit]]-Table3[[#This Row],[Adjustments_Debit]],"") -> 158000 | I29: N/A | J29: =IF(Table3[[#This Row],[HST_Eligible]]="YES",Table3[[#This Row],[Adjusted_Debit]]*0.13,IF(Table3[[#This Row],[Adjusted_Debit]]="Partial",Table3[[#Headers],[Adjusted_Debit]]*0.13*0.5,IF(Table3[[#This Row],[HST_Eligible]]="NO",0,"")))
A31: COST OF GOODS SOLD | G31: =IF(ABS(IF(Table3[[#This Row],[Unadjusted_Debit]]>=0,Table3[[#This Row],[Unadjusted_Debit]]+Table3[[#This Row],[Adjustments_Debit]]-Table3[[#This Row],[Adjustments_Credit]],"0"))=0,"",(ABS(IF(Table3[[#This Row],[Unadjusted_Debit]]>=0,Table3[[#This Row],[Unadjusted_Debit]]+Table3[[#This Row],[Adjustments_Debit]]-Table3[[#This Row],[Adjustments_Credit]],"0")))) | H31: =IF(Table3[[#This Row],[Unadjusted_Credit]]>0,Table3[[#This Row],[Unadjusted_Credit]]+Table3[[#This Row],[Adjustments_Credit]]-Table3[[#This Row],[Adjustments_Debit]],"") | J31: =IF(Table3[[#This Row],[HST_Eligible]]="YES",Table3[[#This Row],[Adjusted_Debit]]*0.13,IF(Table3[[#This Row],[Adjusted_Debit]]="Partial",Table3[[#Headers],[Adjusted_Debit]]*0.13*0.5,IF(Table3[[#This Row],[HST_Eligible]]="NO",0,"")))
A32: 5000 | B32: COGS - New Vehicles | C32: 850000 | G32: =IF(ABS(IF(Table3[[#This Row],[Unadjusted_Debit]]>=0,Table3[[#This Row],[Unadjusted_Debit]]+Table3[[#This Row],[Adjustments_Debit]]-Table3[[#This Row],[Adjustments_Credit]],"0"))=0,"",(ABS(IF(Table3[[#This Row],[Unadjusted_Debit]]>=0,Table3[[#This Row],[Unadjusted_Debit]]+Table3[[#This Row],[Adjustments_Debit]]-Table3[[#This Row],[Adjustments_Credit]],"0")))) -> 850000 | I32: YES | J32: =IF(Table3[[#This Row],[HST_Eligible]]="YES",Table3[[#This Row],[Adjusted_Debit]]*0.13,IF(Table3[[#This Row],[Adjusted_Debit]]="Partial",Table3[[#Headers],[Adjusted_Debit]]*0.13*0.5,IF(Table3[[#This Row],[HST_Eligible]]="NO",0,""))) -> 110500
A33: 5001 | B33: COGS - Used Vehicles | C33: 275000 | G33: =IF(ABS(IF(Table3[[#This Row],[Unadjusted_Debit]]>=0,Table3[[#This Row],[Unadjusted_Debit]]+Table3[[#This Row],[Adjustments_Debit]]-Table3[[#This Row],[Adjustments_Credit]],"0"))=0,"",(ABS(IF(Table3[[#This Row],[Unadjusted_Debit]]>=0,Table3[[#This Row],[Unadjusted_Debit]]+Table3[[#This Row],[Adjustments_Debit]]-Table3[[#This Row],[Adjustments_Credit]],"0")))) -> 275000 | I33: YES | J33: =IF(Table3[[#This Row],[HST_Eligible]]="YES",Table3[[#This Row],[Adjusted_Debit]]*0.13,IF(Table3[[#This Row],[Adjusted_Debit]]="Partial",Table3[[#Headers],[Adjusted_Debit]]*0.13*0.5,IF(Table3[[#This Row],[HST_Eligible]]="NO",0,""))) -> 35750
A34: 5002 | B34: COGS - Parts | C34: 50000 | G34: =IF(ABS(IF(Table3[[#This Row],[Unadjusted_Debit]]>=0,Table3[[#This Row],[Unadjusted_Debit]]+Table3[[#This Row],[Adjustments_Debit]]-Table3[[#This Row],[Adjustments_Credit]],"0"))=0,"",(ABS(IF(Table3[[#This Row],[Unadjusted_Debit]]>=0,Table3[[#This Row],[Unadjusted_Debit]]+Table3[[#This Row],[Adjustments_Debit]]-Table3[[#This Row],[Adjustments_Credit]],"0")))) -> 50000 | I34: YES | J34: =IF(Table3[[#This Row],[HST_Eligible]]="YES",Table3[[#This Row],[Adjusted_Debit]]*0.13,IF(Table3[[#This Row],[Adjusted_Debit]]="Partial",Table3[[#Headers],[Adjusted_Debit]]*0.13*0.5,IF(Table3[[#This Row],[HST_Eligible]]="NO",0,""))) -> 6500
A35: 5003 | B35: Freight & Delivery | C35: 8000 | G35: =IF(ABS(IF(Table3[[#This Row],[Unadjusted_Debit]]>=0,Table3[[#This Row],[Unadjusted_Debit]]+Table3[[#This Row],[Adjustments_Debit]]-Table3[[#This Row],[Adjustments_Credit]],"0"))=0,"",(ABS(IF(Table3[[#This Row],[Unadjusted_Debit]]>=0,Table3[[#This Row],[Unadjusted_Debit]]+Table3[[#This Row],[Adjustments_Debit]]-Table3[[#This Row],[Adjustments_Credit]],"0")))) -> 8000 | I35: YES | J35: =IF(Table3[[#This Row],[HST_Eligible]]="YES",Table3[[#This Row],[Adjusted_Debit]]*0.13,IF(Table3[[#This Row],[Adjusted_Debit]]="Partial",Table3[[#Headers],[Adjusted_Debit]]*0.13*0.5,IF(Table3[[#This Row],[HST_Eligible]]="NO",0,""))) -> 1040
G36: =IF(ABS(IF(Table3[[#This Row],[Unadjusted_Debit]]>=0,Table3[[#This Row],[Unadjusted_Debit]]+Table3[[#This Row],[Adjustments_Debit]]-Table3[[#This Row],[Adjustments_Credit]],"0"))=0,"",(ABS(IF(Table3[[#This Row],[Unadjusted_Debit]]>=0,Table3[[#This Row],[Unadjusted_Debit]]+Table3[[#This Row],[Adjustments_Debit]]-Table3[[#This Row],[Adjustments_Credit]],"0")))) | J36: =IF(Table3[[#This Row],[HST_Eligible]]="YES",Table3[[#This Row],[Adjusted_Debit]]*0.13,IF(Table3[[#This Row],[Adjusted_Debit]]="Partial",Table3[[#Headers],[Adjusted_Debit]]*0.13*0.5,IF(Table3[[#This Row],[HST_Eligible]]="NO",0,"")))
A37: PAYROLL & BENEFITS | G37: =IF(ABS(IF(Table3[[#This Row],[Unadjusted_Debit]]>=0,Table3[[#This Row],[Unadjusted_Debit]]+Table3[[#This Row],[Adjustments_Debit]]-Table3[[#This Row],[Adjustments_Credit]],"0"))=0,"",(ABS(IF(Table3[[#This Row],[Unadjusted_Debit]]>=0,Table3[[#This Row],[Unadjusted_Debit]]+Table3[[#This Row],[Adjustments_Debit]]-Table3[[#This Row],[Adjustments_Credit]],"0")))) | J37: =IF(Table3[[#This Row],[HST_Eligible]]="YES",Table3[[#This Row],[Adjusted_Debit]]*0.13,IF(Table3[[#This Row],[Adjusted_Debit]]="Partial",Table3[[#Headers],[Adjusted_Debit]]*0.13*0.5,IF(Table3[[#This Row],[HST_Eligible]]="NO",0,"")))
A38: 5100 | B38: Salaries & Wages | C38: 285000 | E38: 3400 | G38: =IF(ABS(IF(Table3[[#This Row],[Unadjusted_Debit]]>=0,Table3[[#This Row],[Unadjusted_Debit]]+Table3[[#This Row],[Adjustments_Debit]]-Table3[[#This Row],[Adjustments_Credit]],"0"))=0,"",(ABS(IF(Table3[[#This Row],[Unadjusted_Debit]]>=0,Table3[[#This Row],[Unadjusted_Debit]]+Table3[[#This Row],[Adjustments_Debit]]-Table3[[#This Row],[Adjustments_Credit]],"0")))) -> 288400 | I38: NO | J38: =IF(Table3[[#This Row],[HST_Eligible]]="YES",Table3[[#This Row],[Adjusted_Debit]]*0.13,IF(Table3[[#This Row],[Adjusted_Debit]]="Partial",Table3[[#Headers],[Adjusted_Debit]]*0.13*0.5,IF(Table3[[#This Row],[HST_Eligible]]="NO",0,""))) -> 0
A39: 5105 | B39: Overtime Pay | C39: 5000 | G39: =IF(ABS(IF(Table3[[#This Row],[Unadjusted_Debit]]>=0,Table3[[#This Row],[Unadjusted_Debit]]+Table3[[#This Row],[Adjustments_Debit]]-Table3[[#This Row],[Adjustments_Credit]],"0"))=0,"",(ABS(IF(Table3[[#This Row],[Unadjusted_Debit]]>=0,Table3[[#This Row],[Unadjusted_Debit]]+Table3[[#This Row],[Adjustments_Debit]]-Table3[[#This Row],[Adjustments_Credit]],"0")))) -> 5000 | H39: =SUM(G38:G39) -> 293400 | I39: NO | J39: =IF(Table3[[#This Row],[HST_Eligible]]="YES",Table3[[#This Row],[Adjusted_Debit]]*0.13,IF(Table3[[#This Row],[Adjusted_Debit]]="Partial",Table3[[#Headers],[Adjusted_Debit]]*0.13*0.5,IF(Table3[[#This Row],[HST_Eligible]]="NO",0,""))) -> 0
A40: 5110 | B40: Employee Benefits - Health Insurance | C40: 18500 | G40: =IF(ABS(IF(Table3[[#This Row],[Unadjusted_Debit]]>=0,Table3[[#This Row],[Unadjusted_Debit]]+Table3[[#This Row],[Adjustments_Debit]]-Table3[[#This Row],[Adjustments_Credit]],"0"))=0,"",(ABS(IF(Table3[[#This Row],[Unadjusted_Debit]]>=0,Table3[[#This Row],[Unadjusted_Debit]]+Table3[[#This Row],[Adjustments_Debit]]-Table3[[#This Row],[Adjustments_Credit]],"0")))) -> 18500 | I40: NO | J40: =IF(Table3[[#This Row],[HST_Eligible]]="YES",Table3[[#This Row],[Adjusted_Debit]]*0.13,IF(Table3[[#This Row],[Adjusted_Debit]]="Partial",Table3[[#Headers],[Adjusted_Debit]]*0.13*0.5,IF(Table3[[#This Row],[HST_Eligible]]="NO",0,""))) -> 0
A41: 5115 | B41: Employee Benefits - Dental | C41: 6900 | G41: =IF(ABS(IF(Table3[[#This Row],[Unadjusted_Debit]]>=0,Table3[[#This Row],[Unadjusted_Debit]]+Table3[[#This Row],[Adjustments_Debit]]-Table3[[#This Row],[Adjustments_Credit]],"0"))=0,"",(ABS(IF(Table3[[#This Row],[Unadjusted_Debit]]>=0,Table3[[#This Row],[Unadjusted_Debit]]+Table3[[#This Row],[Adjustments_Debit]]-Table3[[#This Row],[Adjustments_Credit]],"0")))) -> 6900 | I41: NO | J41: =IF(Table3[[#This Row],[HST_Eligible]]="YES",Table3[[#This Row],[Adjusted_Debit]]*0.13,IF(Table3[[#This Row],[Adjusted_Debit]]="Partial",Table3[[#Headers],[Adjusted_Debit]]*0.13*0.5,IF(Table3[[#This Row],[HST_Eligible]]="NO",0,""))) -> 0
...

Sheet 11 HST_Return
A1: HST Return - Q4 2024 (October 1 - December 31, 2024)
A3: Line | B3: Description | C3: Amount
A4: 101 | B4: Total Sales (excl. HST) | C4: =SUM('10 Trial Balance '!D26:D29) -> 2218000
A5: 103 | B5: HST Collected (13%) | C5: =C4*0.13 -> 288340
A6: 105 | B6: Adjustments | C6: 0
A7: 106 | B7: Total Purchases (excl. HST) | C7: =SUMIF(Table3[HST_Eligible],"YES",Table3[Adjusted_Debit]) -> 1378740
A8: 108 | B8: Input Tax Credits (ITC) | C8: =C7*0.13 -> 179236.2
A9: 109 | B9: Net HST (Payable)/Refund | C9: =C5-C8 -> 109103.8
A11: HST PAYABLE: | B11: =C9 -> 109103.8 | C11: Amount to remit to CRA
A13: Payment Due Date: | B13: 45688 | C13: Last day of month following quarter

Sheet 12 HST_Rec&JE
A1: HST PAYABLE ACCOUNT RECONCILIATION
A2: Period: Q4 2024 (Oct 1 - Dec 31, 2024)
A3: Discription | B3: Balance | C3: Notes
A4: OPENING BALANCE (from Trial Balance):
A5: Account 2100 - HST Payable | B5: ='10 Trial Balance '!D17 -> 16900 | C5: (Credit balance from previous period)
A7: ACTIVITY THIS QUARTER:
A8: HST Collected on Sales | B8: ='11 HST_Return'!C5 -> 288340 | C8: (Credit - you owe CRA)
A9: Less: Input Tax Credits | B9: ='11 HST_Return'!C8 -> 179236.2 | C9: (Debit - CRA owes you)
A10: Net HST for Quarter | B10: =B8-B9 -> 109103.8
A12: ENDING BALANCE CALCULATION:
A13: Opening Balance | B13: =B5 -> 16900
A14: Plus: Net HST Q4 | B14: =B10 -> 109103.8
A15: TOTAL HST PAYABLE | B15: =SUM(B13:B14) -> 126003.8 | C15: Amount owing to CRA
A17: BREAKDOWN:
A18: Previous period owing | B18: =B13 -> 16900 | C18: (Should have been paid already)
A19: Current period owing | B19: =B14 -> 109103.8 | C19: (Q4 2024)
A20: TOTAL TO REMIT NOW: | B20: =B15 -> 126003.8
A22: Description | B22: Amount
A23: Payment Details:
A24: HST Registration Number: | B24: ASDCCD123E55
A25: Reporting Period: | B25: Q4 2024 (Oct 1 - Dec 31, 2024)
A26: Return Due Date: | B26: 45688
A27: Payment Due Date: | B27: 45688
A29: AMOUNT BREAKDOWN: (From account 2100)
A30: Previous Balance Owing: | B30: =B13 -> 16900
A31: Current Quarter (Q4 2024): | B31: =B19 -> 109103.8
A32: TOTAL AMOUNT TO PAY: | B32: =SUM(B30:B31) -> 126003.8
A34: PAYMENT METHOD:
A35: CRA My Business Account - Online
A36: Pre-authorized Debit
A37: Wire Transfer | B37: ✅
A38: Cheque (mail to CRA)
A40: Payment Confirmation:
A41: Payment Date: | B41: =A52 -> 45688
A42: Confirmation Number:
A43: Amount Paid: | B43: =B32 -> 126003.8
A44: Payment Method: | B44: =A37 -> Wire Transfer
A46: JOURNAL ENTRIES " HST_Q4"
A47: Date | B47: Entry | C47: Account | D47: Account_Name | E47: Debit | F47: Credit | G47: Memo
A48: 45657 | B48: JE-HST-01 | C48: 2100 | D48: HST Payable | E48: 179236.2 | G48: Record Q4 ITCs
...

Sheet 13 WSIB & EHT
A1: WSIB Annual Premium - 2024
A2: Description | B2: Amount | C2: Calculation / Notes
A3: Total Gross Payroll | B3: ='10 Trial Balance '!G38+'10 Trial Balance '!G39 -> 293400 | C3: =SUM of Salaries & Wages + Overtime (288400 + 5000)
A4: WSIB Rate (per $100 payroll) | B4: 0.85 | C4: 2024 Ontario rate - Automobile & Truck Dealers classification
A5: Annual Premium Due | B5: =B3*B4/100 -> 2493.9 | C5: 293400 * 0.85 / 100
A6: Payment Status | B6: Annual | C6: Report via WSIB online account
A7: Journal Entry - Debit Account | B7: ='10 Trial Balance '!G44 -> 5273 | C7: WSIB Premiums
A8: Journal Entry - Credit Account | B8: ='10 Trial Balance '!H18 -> 21850 | C8: Payroll Liabilities
A9: Due Date | B9: Annual return | C9: Typically with WSIB filing
A11: Employer Health Tax (EHT) - Ontario 2024
A12: Description | B12: Amount | C12: Calculation / Notes
A13: Total Gross Payroll (Ontario) | B13: =B3 -> 293400 | C13: SUM of Salaries & Wages ($288,400) + Overtime ($5,000) from trial balance
A14: EHT Exemption Threshold (2024) | B14: 1000000 | C14: $1,000,000 - permanent since 2020
A15: Taxable Payroll Amount | B15: 0 | C15: =MAX(0, 293400 - 1000000) -> 0
A16: EHT Rate | B16: 0.0195 | C16: Standard rate on taxable payroll
A17: EHT Payable | B17: 0 | C17: =0 * 1.95% -> 0
A18: Associated Employers? | B18: No | C18: Assumed single entity; if group > $5M total payroll → $0 exemption
A19: Eligible for Exemption? | B19: Yes | C19: Payroll < $1M and < $5M group threshold
A20: Filing Required? | B20: Yes | C20: Annual return even if $0
